2021-09-27 21:39:15,679 ERROR: Exception on /news [GET] [in c:\Users\anton\Downloads\Dissertation Folder\NewHowler-1\venv\lib\site-packages\flask\app.py:1454]
Traceback (most recent call last):
  File "c:\Users\anton\Downloads\Dissertation Folder\NewHowler-1\venv\lib\site-packages\flask\app.py", line 2070, in wsgi_app
    response = self.full_dispatch_request()
  File "c:\Users\anton\Downloads\Dissertation Folder\NewHowler-1\venv\lib\site-packages\flask\app.py", line 1515, in full_dispatch_request
    rv = self.handle_user_exception(e)
  File "c:\Users\anton\Downloads\Dissertation Folder\NewHowler-1\venv\lib\site-packages\flask\app.py", line 1513, in full_dispatch_request
    rv = self.dispatch_request()
  File "c:\Users\anton\Downloads\Dissertation Folder\NewHowler-1\venv\lib\site-packages\flask\app.py", line 1499, in dispatch_request
    return self.ensure_sync(self.view_functions[rule.endpoint])(**req.view_args)
  File "c:\Users\anton\Downloads\Dissertation Folder\NewHowler-1\venv\lib\site-packages\flask_login\utils.py", line 272, in decorated_view
    return func(*args, **kwargs)
  File "C:\Users\anton\Downloads\Dissertation Folder\NewHowler-1\app\routes.py", line 27, in news
    render_template('news.html' , title=first_article.get("title"),published=first_article.get("published"),summary=first_article.get("summary"))
  File "c:\Users\anton\Downloads\Dissertation Folder\NewHowler-1\venv\lib\site-packages\feedparser\util.py", line 113, in __getitem__
    return dict.__getitem__(self, key)
KeyError: 'enteries'
2021-09-27 21:39:16,117 ERROR: Exception on /news [GET] [in c:\Users\anton\Downloads\Dissertation Folder\NewHowler-1\venv\lib\site-packages\flask\app.py:1454]
Traceback (most recent call last):
  File "c:\Users\anton\Downloads\Dissertation Folder\NewHowler-1\venv\lib\site-packages\flask\app.py", line 2070, in wsgi_app
    response = self.full_dispatch_request()
  File "c:\Users\anton\Downloads\Dissertation Folder\NewHowler-1\venv\lib\site-packages\flask\app.py", line 1515, in full_dispatch_request
    rv = self.handle_user_exception(e)
  File "c:\Users\anton\Downloads\Dissertation Folder\NewHowler-1\venv\lib\site-packages\flask\app.py", line 1513, in full_dispatch_request
    rv = self.dispatch_request()
  File "c:\Users\anton\Downloads\Dissertation Folder\NewHowler-1\venv\lib\site-packages\flask\app.py", line 1499, in dispatch_request
    return self.ensure_sync(self.view_functions[rule.endpoint])(**req.view_args)
  File "c:\Users\anton\Downloads\Dissertation Folder\NewHowler-1\venv\lib\site-packages\flask_login\utils.py", line 272, in decorated_view
    return func(*args, **kwargs)
  File "C:\Users\anton\Downloads\Dissertation Folder\NewHowler-1\app\routes.py", line 27, in news
    render_template('news.html' , title=first_article.get("title"),published=first_article.get("published"),summary=first_article.get("summary"))
  File "c:\Users\anton\Downloads\Dissertation Folder\NewHowler-1\venv\lib\site-packages\feedparser\util.py", line 113, in __getitem__
    return dict.__getitem__(self, key)
KeyError: 'enteries'
2021-09-27 21:57:59,462 ERROR: Exception on /news [GET] [in c:\Users\anton\Downloads\Dissertation Folder\NewHowler-1\venv\lib\site-packages\flask\app.py:1454]
Traceback (most recent call last):
  File "c:\Users\anton\Downloads\Dissertation Folder\NewHowler-1\venv\lib\site-packages\flask\app.py", line 2070, in wsgi_app
    response = self.full_dispatch_request()
  File "c:\Users\anton\Downloads\Dissertation Folder\NewHowler-1\venv\lib\site-packages\flask\app.py", line 1515, in full_dispatch_request
    rv = self.handle_user_exception(e)
  File "c:\Users\anton\Downloads\Dissertation Folder\NewHowler-1\venv\lib\site-packages\flask\app.py", line 1513, in full_dispatch_request
    rv = self.dispatch_request()
  File "c:\Users\anton\Downloads\Dissertation Folder\NewHowler-1\venv\lib\site-packages\flask\app.py", line 1499, in dispatch_request
    return self.ensure_sync(self.view_functions[rule.endpoint])(**req.view_args)
  File "c:\Users\anton\Downloads\Dissertation Folder\NewHowler-1\venv\lib\site-packages\flask_login\utils.py", line 272, in decorated_view
    return func(*args, **kwargs)
  File "C:\Users\anton\Downloads\Dissertation Folder\NewHowler-1\app\routes.py", line 27, in news
  File "c:\Users\anton\Downloads\Dissertation Folder\NewHowler-1\venv\lib\site-packages\feedparser\util.py", line 113, in __getitem__
    return dict.__getitem__(self, key)
KeyError: 'enteries'
2021-09-27 21:58:00,282 ERROR: Exception on /news [GET] [in c:\Users\anton\Downloads\Dissertation Folder\NewHowler-1\venv\lib\site-packages\flask\app.py:1454]
Traceback (most recent call last):
  File "c:\Users\anton\Downloads\Dissertation Folder\NewHowler-1\venv\lib\site-packages\flask\app.py", line 2070, in wsgi_app
    response = self.full_dispatch_request()
  File "c:\Users\anton\Downloads\Dissertation Folder\NewHowler-1\venv\lib\site-packages\flask\app.py", line 1515, in full_dispatch_request
    rv = self.handle_user_exception(e)
  File "c:\Users\anton\Downloads\Dissertation Folder\NewHowler-1\venv\lib\site-packages\flask\app.py", line 1513, in full_dispatch_request
    rv = self.dispatch_request()
  File "c:\Users\anton\Downloads\Dissertation Folder\NewHowler-1\venv\lib\site-packages\flask\app.py", line 1499, in dispatch_request
    return self.ensure_sync(self.view_functions[rule.endpoint])(**req.view_args)
  File "c:\Users\anton\Downloads\Dissertation Folder\NewHowler-1\venv\lib\site-packages\flask_login\utils.py", line 272, in decorated_view
    return func(*args, **kwargs)
  File "C:\Users\anton\Downloads\Dissertation Folder\NewHowler-1\app\routes.py", line 27, in news
  File "c:\Users\anton\Downloads\Dissertation Folder\NewHowler-1\venv\lib\site-packages\feedparser\util.py", line 113, in __getitem__
    return dict.__getitem__(self, key)
KeyError: 'enteries'
2021-09-27 21:58:01,293 ERROR: Exception on /news [GET] [in c:\Users\anton\Downloads\Dissertation Folder\NewHowler-1\venv\lib\site-packages\flask\app.py:1454]
Traceback (most recent call last):
  File "c:\Users\anton\Downloads\Dissertation Folder\NewHowler-1\venv\lib\site-packages\flask\app.py", line 2070, in wsgi_app
    response = self.full_dispatch_request()
  File "c:\Users\anton\Downloads\Dissertation Folder\NewHowler-1\venv\lib\site-packages\flask\app.py", line 1515, in full_dispatch_request
    rv = self.handle_user_exception(e)
  File "c:\Users\anton\Downloads\Dissertation Folder\NewHowler-1\venv\lib\site-packages\flask\app.py", line 1513, in full_dispatch_request
    rv = self.dispatch_request()
  File "c:\Users\anton\Downloads\Dissertation Folder\NewHowler-1\venv\lib\site-packages\flask\app.py", line 1499, in dispatch_request
    return self.ensure_sync(self.view_functions[rule.endpoint])(**req.view_args)
  File "c:\Users\anton\Downloads\Dissertation Folder\NewHowler-1\venv\lib\site-packages\flask_login\utils.py", line 272, in decorated_view
    return func(*args, **kwargs)
  File "C:\Users\anton\Downloads\Dissertation Folder\NewHowler-1\app\routes.py", line 27, in news
  File "c:\Users\anton\Downloads\Dissertation Folder\NewHowler-1\venv\lib\site-packages\feedparser\util.py", line 113, in __getitem__
    return dict.__getitem__(self, key)
KeyError: 'enteries'
2021-09-27 21:58:03,227 ERROR: Exception on /news [GET] [in c:\Users\anton\Downloads\Dissertation Folder\NewHowler-1\venv\lib\site-packages\flask\app.py:1454]
Traceback (most recent call last):
  File "c:\Users\anton\Downloads\Dissertation Folder\NewHowler-1\venv\lib\site-packages\flask\app.py", line 2070, in wsgi_app
    response = self.full_dispatch_request()
  File "c:\Users\anton\Downloads\Dissertation Folder\NewHowler-1\venv\lib\site-packages\flask\app.py", line 1515, in full_dispatch_request
    rv = self.handle_user_exception(e)
  File "c:\Users\anton\Downloads\Dissertation Folder\NewHowler-1\venv\lib\site-packages\flask\app.py", line 1513, in full_dispatch_request
    rv = self.dispatch_request()
  File "c:\Users\anton\Downloads\Dissertation Folder\NewHowler-1\venv\lib\site-packages\flask\app.py", line 1499, in dispatch_request
    return self.ensure_sync(self.view_functions[rule.endpoint])(**req.view_args)
  File "c:\Users\anton\Downloads\Dissertation Folder\NewHowler-1\venv\lib\site-packages\flask_login\utils.py", line 272, in decorated_view
    return func(*args, **kwargs)
  File "C:\Users\anton\Downloads\Dissertation Folder\NewHowler-1\app\routes.py", line 27, in news
  File "c:\Users\anton\Downloads\Dissertation Folder\NewHowler-1\venv\lib\site-packages\feedparser\util.py", line 113, in __getitem__
    return dict.__getitem__(self, key)
KeyError: 'enteries'
2021-09-27 21:58:49,453 INFO: Howler startup [in C:\Users\anton\Downloads\Dissertation Folder\NewHowler-1\app\__init__.py:67]
2021-09-27 21:58:53,408 ERROR: Exception on /news [GET] [in c:\Users\anton\Downloads\Dissertation Folder\NewHowler-1\venv\lib\site-packages\flask\app.py:1454]
Traceback (most recent call last):
  File "c:\Users\anton\Downloads\Dissertation Folder\NewHowler-1\venv\lib\site-packages\flask\app.py", line 2070, in wsgi_app
    response = self.full_dispatch_request()
  File "c:\Users\anton\Downloads\Dissertation Folder\NewHowler-1\venv\lib\site-packages\flask\app.py", line 1516, in full_dispatch_request
    return self.finalize_request(rv)
  File "c:\Users\anton\Downloads\Dissertation Folder\NewHowler-1\venv\lib\site-packages\flask\app.py", line 1535, in finalize_request
    response = self.make_response(rv)
  File "c:\Users\anton\Downloads\Dissertation Folder\NewHowler-1\venv\lib\site-packages\flask\app.py", line 1698, in make_response
    raise TypeError(
TypeError: The view function for 'news' did not return a valid response. The function either returned None or ended without a return statement.
