2021-09-27 21:30:41,579 ERROR: Exception on /news [GET] [in c:\Users\anton\Downloads\Dissertation Folder\NewHowler-1\venv\lib\site-packages\flask\app.py:1454]
Traceback (most recent call last):
  File "c:\Users\anton\Downloads\Dissertation Folder\NewHowler-1\venv\lib\site-packages\flask\app.py", line 2070, in wsgi_app
    response = self.full_dispatch_request()
  File "c:\Users\anton\Downloads\Dissertation Folder\NewHowler-1\venv\lib\site-packages\flask\app.py", line 1515, in full_dispatch_request
    rv = self.handle_user_exception(e)
  File "c:\Users\anton\Downloads\Dissertation Folder\NewHowler-1\venv\lib\site-packages\flask\app.py", line 1513, in full_dispatch_request
    rv = self.dispatch_request()
  File "c:\Users\anton\Downloads\Dissertation Folder\NewHowler-1\venv\lib\site-packages\flask\app.py", line 1499, in dispatch_request
    return self.ensure_sync(self.view_functions[rule.endpoint])(**req.view_args)
  File "c:\Users\anton\Downloads\Dissertation Folder\NewHowler-1\venv\lib\site-packages\flask_login\utils.py", line 272, in decorated_view
    return func(*args, **kwargs)
  File "C:\Users\anton\Downloads\Dissertation Folder\NewHowler-1\app\routes.py", line 27, in news
    first_article = feed['entries'][0]
  File "c:\Users\anton\Downloads\Dissertation Folder\NewHowler-1\venv\lib\site-packages\feedparser\util.py", line 113, in __getitem__
    return dict.__getitem__(self, key)
KeyError: 'enteries'
2021-09-27 21:30:43,198 ERROR: Exception on /news [GET] [in c:\Users\anton\Downloads\Dissertation Folder\NewHowler-1\venv\lib\site-packages\flask\app.py:1454]
Traceback (most recent call last):
  File "c:\Users\anton\Downloads\Dissertation Folder\NewHowler-1\venv\lib\site-packages\flask\app.py", line 2070, in wsgi_app
    response = self.full_dispatch_request()
  File "c:\Users\anton\Downloads\Dissertation Folder\NewHowler-1\venv\lib\site-packages\flask\app.py", line 1515, in full_dispatch_request
    rv = self.handle_user_exception(e)
  File "c:\Users\anton\Downloads\Dissertation Folder\NewHowler-1\venv\lib\site-packages\flask\app.py", line 1513, in full_dispatch_request
    rv = self.dispatch_request()
  File "c:\Users\anton\Downloads\Dissertation Folder\NewHowler-1\venv\lib\site-packages\flask\app.py", line 1499, in dispatch_request
    return self.ensure_sync(self.view_functions[rule.endpoint])(**req.view_args)
  File "c:\Users\anton\Downloads\Dissertation Folder\NewHowler-1\venv\lib\site-packages\flask_login\utils.py", line 272, in decorated_view
    return func(*args, **kwargs)
  File "C:\Users\anton\Downloads\Dissertation Folder\NewHowler-1\app\routes.py", line 27, in news
    first_article = feed['entries'][0]
  File "c:\Users\anton\Downloads\Dissertation Folder\NewHowler-1\venv\lib\site-packages\feedparser\util.py", line 113, in __getitem__
    return dict.__getitem__(self, key)
KeyError: 'enteries'
2021-09-27 21:32:54,848 ERROR: Exception on /news [GET] [in c:\Users\anton\Downloads\Dissertation Folder\NewHowler-1\venv\lib\site-packages\flask\app.py:1454]
Traceback (most recent call last):
  File "c:\Users\anton\Downloads\Dissertation Folder\NewHowler-1\venv\lib\site-packages\flask\app.py", line 2070, in wsgi_app
    response = self.full_dispatch_request()
  File "c:\Users\anton\Downloads\Dissertation Folder\NewHowler-1\venv\lib\site-packages\flask\app.py", line 1515, in full_dispatch_request
    rv = self.handle_user_exception(e)
  File "c:\Users\anton\Downloads\Dissertation Folder\NewHowler-1\venv\lib\site-packages\flask\app.py", line 1513, in full_dispatch_request
    rv = self.dispatch_request()
  File "c:\Users\anton\Downloads\Dissertation Folder\NewHowler-1\venv\lib\site-packages\flask\app.py", line 1499, in dispatch_request
    return self.ensure_sync(self.view_functions[rule.endpoint])(**req.view_args)
  File "c:\Users\anton\Downloads\Dissertation Folder\NewHowler-1\venv\lib\site-packages\flask_login\utils.py", line 272, in decorated_view
    return func(*args, **kwargs)
  File "C:\Users\anton\Downloads\Dissertation Folder\NewHowler-1\app\routes.py", line 27, in news
    first_article = feed['entries'][0]
  File "c:\Users\anton\Downloads\Dissertation Folder\NewHowler-1\venv\lib\site-packages\feedparser\util.py", line 113, in __getitem__
    return dict.__getitem__(self, key)
KeyError: 'enteries'
2021-09-27 21:32:55,332 ERROR: Exception on /news [GET] [in c:\Users\anton\Downloads\Dissertation Folder\NewHowler-1\venv\lib\site-packages\flask\app.py:1454]
Traceback (most recent call last):
  File "c:\Users\anton\Downloads\Dissertation Folder\NewHowler-1\venv\lib\site-packages\flask\app.py", line 2070, in wsgi_app
    response = self.full_dispatch_request()
  File "c:\Users\anton\Downloads\Dissertation Folder\NewHowler-1\venv\lib\site-packages\flask\app.py", line 1515, in full_dispatch_request
    rv = self.handle_user_exception(e)
  File "c:\Users\anton\Downloads\Dissertation Folder\NewHowler-1\venv\lib\site-packages\flask\app.py", line 1513, in full_dispatch_request
    rv = self.dispatch_request()
  File "c:\Users\anton\Downloads\Dissertation Folder\NewHowler-1\venv\lib\site-packages\flask\app.py", line 1499, in dispatch_request
    return self.ensure_sync(self.view_functions[rule.endpoint])(**req.view_args)
  File "c:\Users\anton\Downloads\Dissertation Folder\NewHowler-1\venv\lib\site-packages\flask_login\utils.py", line 272, in decorated_view
    return func(*args, **kwargs)
  File "C:\Users\anton\Downloads\Dissertation Folder\NewHowler-1\app\routes.py", line 27, in news
    first_article = feed['entries'][0]
  File "c:\Users\anton\Downloads\Dissertation Folder\NewHowler-1\venv\lib\site-packages\feedparser\util.py", line 113, in __getitem__
    return dict.__getitem__(self, key)
KeyError: 'enteries'
2021-09-27 21:35:36,437 ERROR: Exception on /news [GET] [in c:\Users\anton\Downloads\Dissertation Folder\NewHowler-1\venv\lib\site-packages\flask\app.py:1454]
Traceback (most recent call last):
  File "c:\Users\anton\Downloads\Dissertation Folder\NewHowler-1\venv\lib\site-packages\flask\app.py", line 2070, in wsgi_app
    response = self.full_dispatch_request()
  File "c:\Users\anton\Downloads\Dissertation Folder\NewHowler-1\venv\lib\site-packages\flask\app.py", line 1515, in full_dispatch_request
    rv = self.handle_user_exception(e)
  File "c:\Users\anton\Downloads\Dissertation Folder\NewHowler-1\venv\lib\site-packages\flask\app.py", line 1513, in full_dispatch_request
    rv = self.dispatch_request()
  File "c:\Users\anton\Downloads\Dissertation Folder\NewHowler-1\venv\lib\site-packages\flask\app.py", line 1499, in dispatch_request
    return self.ensure_sync(self.view_functions[rule.endpoint])(**req.view_args)
  File "c:\Users\anton\Downloads\Dissertation Folder\NewHowler-1\venv\lib\site-packages\flask_login\utils.py", line 272, in decorated_view
    return func(*args, **kwargs)
  File "C:\Users\anton\Downloads\Dissertation Folder\NewHowler-1\app\routes.py", line 27, in news
    first_article = feed['entries'][0]
  File "c:\Users\anton\Downloads\Dissertation Folder\NewHowler-1\venv\lib\site-packages\feedparser\util.py", line 113, in __getitem__
    return dict.__getitem__(self, key)
KeyError: 'enteries'
2021-09-27 21:35:37,838 ERROR: Exception on /news [GET] [in c:\Users\anton\Downloads\Dissertation Folder\NewHowler-1\venv\lib\site-packages\flask\app.py:1454]
Traceback (most recent call last):
  File "c:\Users\anton\Downloads\Dissertation Folder\NewHowler-1\venv\lib\site-packages\flask\app.py", line 2070, in wsgi_app
    response = self.full_dispatch_request()
  File "c:\Users\anton\Downloads\Dissertation Folder\NewHowler-1\venv\lib\site-packages\flask\app.py", line 1515, in full_dispatch_request
    rv = self.handle_user_exception(e)
  File "c:\Users\anton\Downloads\Dissertation Folder\NewHowler-1\venv\lib\site-packages\flask\app.py", line 1513, in full_dispatch_request
    rv = self.dispatch_request()
  File "c:\Users\anton\Downloads\Dissertation Folder\NewHowler-1\venv\lib\site-packages\flask\app.py", line 1499, in dispatch_request
    return self.ensure_sync(self.view_functions[rule.endpoint])(**req.view_args)
  File "c:\Users\anton\Downloads\Dissertation Folder\NewHowler-1\venv\lib\site-packages\flask_login\utils.py", line 272, in decorated_view
    return func(*args, **kwargs)
  File "C:\Users\anton\Downloads\Dissertation Folder\NewHowler-1\app\routes.py", line 27, in news
    first_article = feed['entries'][0]
  File "c:\Users\anton\Downloads\Dissertation Folder\NewHowler-1\venv\lib\site-packages\feedparser\util.py", line 113, in __getitem__
    return dict.__getitem__(self, key)
KeyError: 'enteries'
2021-09-27 21:35:38,200 ERROR: Exception on /news [GET] [in c:\Users\anton\Downloads\Dissertation Folder\NewHowler-1\venv\lib\site-packages\flask\app.py:1454]
Traceback (most recent call last):
  File "c:\Users\anton\Downloads\Dissertation Folder\NewHowler-1\venv\lib\site-packages\flask\app.py", line 2070, in wsgi_app
    response = self.full_dispatch_request()
  File "c:\Users\anton\Downloads\Dissertation Folder\NewHowler-1\venv\lib\site-packages\flask\app.py", line 1515, in full_dispatch_request
    rv = self.handle_user_exception(e)
  File "c:\Users\anton\Downloads\Dissertation Folder\NewHowler-1\venv\lib\site-packages\flask\app.py", line 1513, in full_dispatch_request
    rv = self.dispatch_request()
  File "c:\Users\anton\Downloads\Dissertation Folder\NewHowler-1\venv\lib\site-packages\flask\app.py", line 1499, in dispatch_request
    return self.ensure_sync(self.view_functions[rule.endpoint])(**req.view_args)
  File "c:\Users\anton\Downloads\Dissertation Folder\NewHowler-1\venv\lib\site-packages\flask_login\utils.py", line 272, in decorated_view
    return func(*args, **kwargs)
  File "C:\Users\anton\Downloads\Dissertation Folder\NewHowler-1\app\routes.py", line 27, in news
    first_article = feed['entries'][0]
  File "c:\Users\anton\Downloads\Dissertation Folder\NewHowler-1\venv\lib\site-packages\feedparser\util.py", line 113, in __getitem__
    return dict.__getitem__(self, key)
KeyError: 'enteries'
